ERROR:root:'recruitment_costs'
Traceback (most recent call last):
  File "C:\Users\vikto\Documents\Old computer files\SFA\Scramble_for_Africa.py", line 323, in <module>
    global_manager.get('recruitment_costs')['slave workers'] = 5
  File "C:\Users\vikto\Documents\Old computer files\SFA\modules\data_managers.py", line 38, in get
    return(self.global_dict[name])
KeyError: 'recruitment_costs'
